<?xml version="1.0" encoding="utf-8"?>
<!-- This URDF was automatically created by SolidWorks to URDF Exporter! Originally created by Stephen Brawner (brawner@gmail.com) 
     Commit Version: 1.6.0-4-g7f85cfe  Build Version: 1.6.7995.38578
     For more information, please see http://wiki.ros.org/sw_urdf_exporter -->
<robot
  name="ic_arm_8dof">
  <link
    name="base_link">
    <inertial>
      <origin
        xyz="0.0550749689718998 0.0489848323102013 0.0485936803116444"
        rpy="0 0 0" />
      <mass
        value="1.00093152576365" />
      <inertia
        ixx="0.00411877569545803"
        ixy="-7.0952835702348E-05"
        ixz="-7.28472751523942E-05"
        iyy="0.00245084831099956"
        iyz="-0.000690438339477277"
        izz="0.00249960910336744" />
    </inertial>
    <visual>
      <origin
        xyz="0 0 0"
        rpy="0 0 0" />
      <geometry>
        <mesh
          filename="package://ic_arm_8dof/meshes/base_link.STL" />
      </geometry>
      <material
        name="">
        <color
          rgba="1 1 1 1" />
      </material>
    </visual>
    <collision>
      <origin
        xyz="0 0 0"
        rpy="0 0 0" />
      <geometry>
        <mesh
          filename="package://ic_arm_8dof/meshes/base_link.STL" />
      </geometry>
    </collision>
  </link>
  <link
    name="link1">
    <inertial>
      <origin
        xyz="0.0760900373611013 -0.00153648117596858 0.0243448806660543"
        rpy="0 0 0" />
      <mass
        value="0.169504526050837" />
      <inertia
        ixx="0.000104591316083155"
        ixy="2.39696730625234E-06"
        ixz="1.41363090637177E-06"
        iyy="0.000279199940535283"
        iyz="-7.73253117827918E-09"
        izz="0.000292677872316866" />
    </inertial>
    <visual>
      <origin
        xyz="0 0 0"
        rpy="0 0 0" />
      <geometry>
        <mesh
          filename="package://ic_arm_8dof/meshes/link1.STL" />
      </geometry>
      <material
        name="">
        <color
          rgba="0.752941176470588 0.752941176470588 0.752941176470588 1" />
      </material>
    </visual>
    <collision>
      <origin
        xyz="0 0 0"
        rpy="0 0 0" />
      <geometry>
        <mesh
          filename="package://ic_arm_8dof/meshes/link1.STL" />
      </geometry>
    </collision>
  </link>
  <joint
    name="joint1"
    type="revolute">
    <origin
      xyz="0.0398 0.14284 0.14284"
      rpy="1.5708 0 1.5708" />
    <parent
      link="base_link" />
    <child
      link="link1" />
    <axis
      xyz="0 0 -1" />
    <limit
      lower="-3.14"
      upper="3.14"
      effort="0"
      velocity="0" />
  </joint>
  <link
    name="link2">
    <inertial>
      <origin
        xyz="-0.00176862651187626 0.0768489023839996 0.0257884540640424"
        rpy="0 0 0" />
      <mass
        value="0.194122042016285" />
      <inertia
        ixx="0.000337809617037314"
        ixy="5.57394783442434E-06"
        ixz="-2.66771436275802E-10"
        iyy="0.000172093062695412"
        iyz="1.14340046029739E-07"
        izz="0.000321609427001858" />
    </inertial>
    <visual>
      <origin
        xyz="0 0 0"
        rpy="0 0 0" />
      <geometry>
        <mesh
          filename="package://ic_arm_8dof/meshes/link2.STL" />
      </geometry>
      <material
        name="">
        <color
          rgba="0.698039215686274 0.698039215686274 0.698039215686274 1" />
      </material>
    </visual>
    <collision>
      <origin
        xyz="0 0 0"
        rpy="0 0 0" />
      <geometry>
        <mesh
          filename="package://ic_arm_8dof/meshes/link2.STL" />
      </geometry>
    </collision>
  </link>
  <joint
    name="joint2"
    type="revolute">
    <origin
      xyz="0.155 0.025825 0.023824"
      rpy="1.5708 0 0" />
    <parent
      link="link1" />
    <child
      link="link2" />
    <axis
      xyz="0 0 1" />
    <limit
      lower="-3.14"
      upper="3.14"
      effort="0"
      velocity="0" />
  </joint>
  <link
    name="link3">
    <inertial>
      <origin
        xyz="1.88216825349474E-05 -0.0704563095901979 0.0279228379570065"
        rpy="0 0 0" />
      <mass
        value="0.243379782381479" />
      <inertia
        ixx="0.000154014413173473"
        ixy="-2.78091630658439E-08"
        ixz="6.80218146937761E-09"
        iyy="0.0001236336830653"
        iyz="-1.5314202656309E-07"
        izz="0.000189584077985161" />
    </inertial>
    <visual>
      <origin
        xyz="0 0 0"
        rpy="0 0 0" />
      <geometry>
        <mesh
          filename="package://ic_arm_8dof/meshes/link3.STL" />
      </geometry>
      <material
        name="">
        <color
          rgba="0.698039215686274 0.698039215686274 0.698039215686274 1" />
      </material>
    </visual>
    <collision>
      <origin
        xyz="0 0 0"
        rpy="0 0 0" />
      <geometry>
        <mesh
          filename="package://ic_arm_8dof/meshes/link3.STL" />
      </geometry>
    </collision>
  </link>
  <joint
    name="joint3"
    type="revolute">
    <origin
      xyz="0.0313 0.13 0.02605"
      rpy="-1.5708 0 1.5708" />
    <parent
      link="link2" />
    <child
      link="link3" />
    <axis
      xyz="0 0 1" />
    <limit
      lower="-3.14"
      upper="3.14"
      effort="0"
      velocity="0" />
  </joint>
  <link
    name="link4">
    <inertial>
      <origin
        xyz="-0.018795586911264 -0.00336797609767844 0.178361055285414"
        rpy="0 0 0" />
      <mass
        value="0.468301114203238" />
      <inertia
        ixx="0.00143245026504016"
        ixy="-2.03674186102041E-05"
        ixz="2.67540964419349E-05"
        iyy="0.00141635865392866"
        iyz="6.23430615294949E-06"
        izz="0.000334287371279185" />
    </inertial>
    <visual>
      <origin
        xyz="0 0 0"
        rpy="0 0 0" />
      <geometry>
        <mesh
          filename="package://ic_arm_8dof/meshes/link4.STL" />
      </geometry>
      <material
        name="">
        <color
          rgba="0.698039215686274 0.698039215686274 0.698039215686274 1" />
      </material>
    </visual>
    <collision>
      <origin
        xyz="0 0 0"
        rpy="0 0 0" />
      <geometry>
        <mesh
          filename="package://ic_arm_8dof/meshes/link4.STL" />
      </geometry>
    </collision>
  </link>
  <joint
    name="joint4"
    type="revolute">
    <origin
      xyz="0 -0.08395 0.02805"
      rpy="1.5708 1.5708 0" />
    <parent
      link="link3" />
    <child
      link="link4" />
    <axis
      xyz="0 0 1" />
    <limit
      lower="-3.14"
      upper="3.14"
      effort="0"
      velocity="0" />
  </joint>
  <link
    name="link5">
    <inertial>
      <origin
        xyz="-0.0551817970996639 -0.0572637721136841 -0.0272819966361564"
        rpy="0 0 0" />
      <mass
        value="0.312463623855098" />
      <inertia
        ixx="0.000592524184632913"
        ixy="-8.54974456132626E-05"
        ixz="-0.00019918463047588"
        iyy="0.000836156497748374"
        iyz="-7.51676734469655E-05"
        izz="0.000700872597290382" />
    </inertial>
    <visual>
      <origin
        xyz="0 0 0"
        rpy="0 0 0" />
      <geometry>
        <mesh
          filename="package://ic_arm_8dof/meshes/link5.STL" />
      </geometry>
      <material
        name="">
        <color
          rgba="0.698039215686274 0.698039215686274 0.698039215686274 1" />
      </material>
    </visual>
    <collision>
      <origin
        xyz="0 0 0"
        rpy="0 0 0" />
      <geometry>
        <mesh
          filename="package://ic_arm_8dof/meshes/link5.STL" />
      </geometry>
    </collision>
  </link>
  <joint
    name="joint5"
    type="revolute">
    <origin
      xyz="-0.02575 0 0.28435"
      rpy="-1.5708 0 -1.5708" />
    <parent
      link="link4" />
    <child
      link="link5" />
    <axis
      xyz="0 0 1" />
    <limit
      lower="-3.14"
      upper="3.14"
      effort="0"
      velocity="0" />
  </joint>
  <link
    name="link6">
    <inertial>
      <origin
        xyz="0.000534822271383295 0.000218584653321585 0.185906461858412"
        rpy="0 0 0" />
      <mass
        value="1.10346766636461" />
      <inertia
        ixx="0.00123458322127103"
        ixy="-3.31801448363204E-07"
        ixz="6.47660213940763E-07"
        iyy="0.00144008784459449"
        iyz="-7.53499156477143E-06"
        izz="0.000624166255434992" />
    </inertial>
    <visual>
      <origin
        xyz="0 0 0"
        rpy="0 0 0" />
      <geometry>
        <mesh
          filename="package://ic_arm_8dof/meshes/link6.STL" />
      </geometry>
      <material
        name="">
        <color
          rgba="1 1 1 1" />
      </material>
    </visual>
    <collision>
      <origin
        xyz="0 0 0"
        rpy="0 0 0" />
      <geometry>
        <mesh
          filename="package://ic_arm_8dof/meshes/link6.STL" />
      </geometry>
    </collision>
  </link>
  <joint
    name="joint6"
    type="revolute">
    <origin
      xyz="-0.090162 -0.04895 -0.06565"
      rpy="1.5708 -1.5708 0" />
    <parent
      link="link5" />
    <child
      link="link6" />
    <axis
      xyz="0 0 1" />
    <limit
      lower="-3.14"
      upper="3.14"
      effort="0"
      velocity="0" />
  </joint>
</robot>