<?xml version="1.0" encoding="utf-8"?>
<!-- This URDF was automatically created by SolidWorks to URDF Exporter! Originally created by Stephen Brawner (brawner@gmail.com) 
     Commit Version: 1.6.0-4-g7f85cfe  Build Version: 1.6.7995.38578
     For more information, please see http://wiki.ros.org/sw_urdf_exporter -->
<robot
  name="ic_arm">
  <link
    name="base_link">
    <inertial>
      <origin
        xyz="-0.06 -0.11358 -0.042345"
        rpy="0 0 0" />
      <mass
        value="0.53699" />
      <inertia
        ixx="0.00084022"
        ixy="7.4151E-20"
        ixz="-3.9525E-20"
        iyy="0.00084022"
        iyz="-2.9178E-19"
        izz="0.0012299" />
    </inertial>
    <visual>
      <origin
        xyz="0 0 0"
        rpy="0 0 0" />
      <geometry>
        <mesh
          filename="/Users/lr-2002/project/instantcreation/IC_arm_control/ic_arm/meshes/base_link.STL" />
      </geometry>
      <material
        name="">
        <color
          rgba="1 1 1 1" />
      </material>
    </visual>
    <collision>
      <origin
        xyz="0 0 0"
        rpy="0 0 0" />
      <geometry>
        <mesh
          filename="/Users/lr-2002/project/instantcreation/IC_arm_control/ic_arm/meshes/base_link.STL" />
      </geometry>
    </collision>
  </link>
  <link
    name="link1">
    <inertial>
      <origin
        xyz="0.11374 0.025923 -0.00060398"
        rpy="0 0 0" />
      <mass
        value="0.5014" />
      <inertia
        ixx="0.0010413"
        ixy="0.00013799"
        ixz="2.7655E-05"
        iyy="0.00422"
        iyz="1.3794E-06"
        izz="0.0035828" />
    </inertial>
    <visual>
      <origin
        xyz="0 0 0"
        rpy="0 0 0" />
      <geometry>
        <mesh
          filename="/Users/lr-2002/project/instantcreation/IC_arm_control/ic_arm/meshes/link1.STL" />
      </geometry>
      <material
        name="">
        <color
          rgba="0.69804 0.69804 0.69804 1" />
      </material>
    </visual>
    <collision>
      <origin
        xyz="0 0 0"
        rpy="0 0 0" />
      <geometry>
        <mesh
          filename="/Users/lr-2002/project/instantcreation/IC_arm_control/ic_arm/meshes/link1.STL" />
      </geometry>
    </collision>
  </link>
  <joint
    name="ba-l1"
    type="fixed">
    <origin
      xyz="-0.10243 0.0955 -0.071158"
      rpy="0 -0.7854 3.1416" />
    <parent
      link="base_link" />
    <child
      link="link1" />
    <axis
      xyz="0 0 0" />
  </joint>
  <link
    name="notor1">
    <inertial>
      <origin
        xyz="-0.011405 -0.053732 -0.0018481"
        rpy="0 0 0" />
      <mass
        value="5.1E-06" />
      <inertia
        ixx="2.9492E-10"
        ixy="-2.4202E-13"
        ixz="-1.4129E-11"
        iyy="1.3871E-10"
        iyz="6.4851E-14"
        izz="2.3985E-10" />
    </inertial>
    <visual>
      <origin
        xyz="0 0 0"
        rpy="0 0 0" />
      <geometry>
        <mesh
          filename="/Users/lr-2002/project/instantcreation/IC_arm_control/ic_arm/meshes/notor1.STL" />
      </geometry>
      <material
        name="">
        <color
          rgba="0.75294 0.75294 0.75294 1" />
      </material>
    </visual>
    <collision>
      <origin
        xyz="0 0 0"
        rpy="0 0 0" />
      <geometry>
        <mesh
          filename="/Users/lr-2002/project/instantcreation/IC_arm_control/ic_arm/meshes/notor1.STL" />
      </geometry>
    </collision>
  </link>
  <joint
    name="join1"
    type="fixed">
    <origin
      xyz="0.182 -0.0027355 0"
      rpy="0 -0.58613 3.1416" />
    <parent
      link="link1" />
    <child
      link="notor1" />
    <axis
      xyz="0 0 0" />
  </joint>
  <link
    name="link2">
    <inertial>
      <origin
        xyz="0.11131 0.015586 0.00010431"
        rpy="0 0 0" />
      <mass
        value="0.24647" />
      <inertia
        ixx="0.0003848"
        ixy="0.00018751"
        ixz="-7.7475E-07"
        iyy="0.0006457"
        iyz="-4.4654E-08"
        izz="0.00082112" />
    </inertial>
    <visual>
      <origin
        xyz="0 0 0"
        rpy="0 0 0" />
      <geometry>
        <mesh
          filename="/Users/lr-2002/project/instantcreation/IC_arm_control/ic_arm/meshes/link2.STL" />
      </geometry>
      <material
        name="">
        <color
          rgba="0.69804 0.69804 0.69804 1" />
      </material>
    </visual>
    <collision>
      <origin
        xyz="0 0 0"
        rpy="0 0 0" />
      <geometry>
        <mesh
          filename="/Users/lr-2002/project/instantcreation/IC_arm_control/ic_arm/meshes/link2.STL" />
      </geometry>
    </collision>
  </link>
  <joint
    name="m1-l2"
    type="continuous">
    <origin
      xyz="0 0 0"
      rpy="0 0.21178 3.1416" />
    <parent
      link="notor1" />
    <child
      link="link2" />
    <axis
      xyz="0 1 0" />
  </joint>
  <link
    name="motor2">
    <inertial>
      <origin
        xyz="0.1118 0.033957 -0.00014359"
        rpy="0 0 0" />
      <mass
        value="0.11836" />
      <inertia
        ixx="4.1228E-05"
        ixy="-4.787E-11"
        ixz="-2.8556E-08"
        iyy="4.8559E-05"
        iyz="1.872E-08"
        izz="4.1296E-05" />
    </inertial>
    <visual>
      <origin
        xyz="0 0 0"
        rpy="0 0 0" />
      <geometry>
        <mesh
          filename="/Users/lr-2002/project/instantcreation/IC_arm_control/ic_arm/meshes/motor2.STL" />
      </geometry>
      <material
        name="">
        <color
          rgba="0.62745 0.62745 0.64314 1" />
      </material>
    </visual>
    <collision>
      <origin
        xyz="0 0 0"
        rpy="0 0 0" />
      <geometry>
        <mesh
          filename="/Users/lr-2002/project/instantcreation/IC_arm_control/ic_arm/meshes/motor2.STL" />
      </geometry>
    </collision>
  </link>
  <joint
    name="joint2"
    type="fixed">
    <origin
      xyz="0.25731 -0.055576 -0.11098"
      rpy="3.1416 -1.5569 -1.5708" />
    <parent
      link="link2" />
    <child
      link="motor2" />
    <axis
      xyz="0 0 0" />
  </joint>
  <link
    name="link3">
    <inertial>
      <origin
        xyz="0.028389 -0.038328 -2.1221E-10"
        rpy="0 0 0" />
      <mass
        value="0.10333" />
      <inertia
        ixx="4.4496E-05"
        ixy="-1.631E-07"
        ixz="5.468E-14"
        iyy="0.00010556"
        iyz="3.2186E-12"
        izz="7.8301E-05" />
    </inertial>
    <visual>
      <origin
        xyz="0 0 0"
        rpy="0 0 0" />
      <geometry>
        <mesh
          filename="/Users/lr-2002/project/instantcreation/IC_arm_control/ic_arm/meshes/link3.STL" />
      </geometry>
      <material
        name="">
        <color
          rgba="0.69804 0.69804 0.69804 1" />
      </material>
    </visual>
    <collision>
      <origin
        xyz="0 0 0"
        rpy="0 0 0" />
      <geometry>
        <mesh
          filename="/Users/lr-2002/project/instantcreation/IC_arm_control/ic_arm/meshes/link3.STL" />
      </geometry>
    </collision>
  </link>
  <joint
    name="m2-l3"
    type="continuous">
    <origin
      xyz="0.1118 0 0"
      rpy="0 0 3.1416" />
    <parent
      link="motor2" />
    <child
      link="link3" />
    <axis
      xyz="0 1 0" />
  </joint>
  <link
    name="motor3">
    <inertial>
      <origin
        xyz="0.11184 0.033957 1.2663E-05"
        rpy="0 0 0" />
      <mass
        value="0.11836" />
      <inertia
        ixx="4.1278E-05"
        ixy="1.1455E-08"
        ixz="2.1899E-08"
        iyy="4.8559E-05"
        iyz="3.5742E-08"
        izz="4.1247E-05" />
    </inertial>
    <visual>
      <origin
        xyz="0 0 0"
        rpy="0 0 0" />
      <geometry>
        <mesh
          filename="/Users/lr-2002/project/instantcreation/IC_arm_control/ic_arm/meshes/motor3.STL" />
      </geometry>
      <material
        name="">
        <color
          rgba="0.62745 0.62745 0.64314 1" />
      </material>
    </visual>
    <collision>
      <origin
        xyz="0 0 0"
        rpy="0 0 0" />
      <geometry>
        <mesh
          filename="/Users/lr-2002/project/instantcreation/IC_arm_control/ic_arm/meshes/motor3.STL" />
      </geometry>
    </collision>
  </link>
  <joint
    name="joint3"
    type="fixed">
    <origin
      xyz="0.060993 0.017193 -0.096822"
      rpy="0 -1.0472 -1.5708" />
    <parent
      link="link3" />
    <child
      link="motor3" />
    <axis
      xyz="0 0 0" />
  </joint>
  <link
    name="link4">
    <inertial>
      <origin
        xyz="0.018271 -0.14695 -0.00074288"
        rpy="0 0 0" />
      <mass
        value="0.33396" />
      <inertia
        ixx="0.0013927"
        ixy="5.5835E-05"
        ixz="9.5717E-06"
        iyy="0.00039863"
        iyz="-3.2438E-06"
        izz="0.0014754" />
    </inertial>
    <visual>
      <origin
        xyz="0 0 0"
        rpy="0 0 0" />
      <geometry>
        <mesh
          filename="/Users/lr-2002/project/instantcreation/IC_arm_control/ic_arm/meshes/link4.STL" />
      </geometry>
      <material
        name="">
        <color
          rgba="0.69804 0.69804 0.69804 1" />
      </material>
    </visual>
    <collision>
      <origin
        xyz="0 0 0"
        rpy="0 0 0" />
      <geometry>
        <mesh
          filename="/Users/lr-2002/project/instantcreation/IC_arm_control/ic_arm/meshes/link4.STL" />
      </geometry>
    </collision>
  </link>
  <joint
    name="m3-l4"
    type="continuous">
    <origin
      xyz="0.1118 0.01022 0"
      rpy="-3.1416 0.99332 0" />
    <parent
      link="motor3" />
    <child
      link="link4" />
    <axis
      xyz="0 1 0" />
  </joint>
  <link
    name="motor4">
    <inertial>
      <origin
        xyz="0.11182 0.033957 -4.8275E-05"
        rpy="0 0 0" />
      <mass
        value="0.11836" />
      <inertia
        ixx="4.1259E-05"
        ixy="7.2976E-09"
        ixz="-5.8869E-08"
        iyy="4.8559E-05"
        iyz="1.6803E-08"
        izz="4.1265E-05" />
    </inertial>
    <visual>
      <origin
        xyz="0 0 0"
        rpy="0 0 0" />
      <geometry>
        <mesh
          filename="/Users/lr-2002/project/instantcreation/IC_arm_control/ic_arm/meshes/motor4.STL" />
      </geometry>
      <material
        name="">
        <color
          rgba="0.62745 0.62745 0.64314 1" />
      </material>
    </visual>
    <collision>
      <origin
        xyz="0 0 0"
        rpy="0 0 0" />
      <geometry>
        <mesh
          filename="/Users/lr-2002/project/instantcreation/IC_arm_control/ic_arm/meshes/motor4.STL" />
      </geometry>
    </collision>
  </link>
  <joint
    name="joint4"
    type="fixed">
    <origin
      xyz="0.038707 -0.19471 -0.062982"
      rpy="-3.1416 -0.59843 -1.5708" />
    <parent
      link="link4" />
    <child
      link="motor4" />
    <axis
      xyz="0 0 0" />
  </joint>
  <link
    name="link5">
    <inertial>
      <origin
        xyz="-0.065523 -0.010775 0.030027"
        rpy="0 0 0" />
      <mass
        value="0.21836" />
      <inertia
        ixx="0.00086076"
        ixy="0.00011477"
        ixz="0.00014583"
        iyy="0.00085159"
        iyz="-0.0002093"
        izz="0.00072958" />
    </inertial>
    <visual>
      <origin
        xyz="0 0 0"
        rpy="0 0 0" />
      <geometry>
        <mesh
          filename="/Users/lr-2002/project/instantcreation/IC_arm_control/ic_arm/meshes/link5.STL" />
      </geometry>
      <material
        name="">
        <color
          rgba="0.69804 0.69804 0.69804 1" />
      </material>
    </visual>
    <collision>
      <origin
        xyz="0 0 0"
        rpy="0 0 0" />
      <geometry>
        <mesh
          filename="/Users/lr-2002/project/instantcreation/IC_arm_control/ic_arm/meshes/link5.STL" />
      </geometry>
    </collision>
  </link>
  <joint
    name="m4-l5"
    type="continuous">
    <origin
      xyz="0.1118 0 0"
      rpy="0 0.57266 -3.1416" />
    <parent
      link="motor4" />
    <child
      link="link5" />
    <axis
      xyz="0 1 0" />
  </joint>
  <link
    name="motor5">
    <inertial>
      <origin
        xyz="0.11181 0.034057 -5.171E-05"
        rpy="0 0 0" />
      <mass
        value="0.11836" />
      <inertia
        ixx="4.124E-05"
        ixy="-1.9853E-08"
        ixz="-1.7125E-09"
        iyy="4.8559E-05"
        iyz="6.6781E-09"
        izz="4.1284E-05" />
    </inertial>
    <visual>
      <origin
        xyz="0 0 0"
        rpy="0 0 0" />
      <geometry>
        <mesh
          filename="/Users/lr-2002/project/instantcreation/IC_arm_control/ic_arm/meshes/motor5.STL" />
      </geometry>
      <material
        name="">
        <color
          rgba="0.69804 0.69804 0.69804 1" />
      </material>
    </visual>
    <collision>
      <origin
        xyz="0 0 0"
        rpy="0 0 0" />
      <geometry>
        <mesh
          filename="/Users/lr-2002/project/instantcreation/IC_arm_control/ic_arm/meshes/motor5.STL" />
      </geometry>
    </collision>
  </link>
  <joint
    name="joint5"
    type="fixed">
    <origin
      xyz="-0.060894 0.083192 -0.017398"
      rpy="3.1416 -1.2945 -1.5708" />
    <parent
      link="link5" />
    <child
      link="motor5" />
    <axis
      xyz="0 0 0" />
  </joint>
  <link
    name="link6">
    <inertial>
      <origin
        xyz="0.0040593 -0.0026972 -0.060275"
        rpy="0 0 0" />
      <mass
        value="0.069293" />
      <inertia
        ixx="0.00016773"
        ixy="-1.2242E-06"
        ixz="6.9929E-06"
        iyy="0.00016928"
        iyz="7.3117E-06"
        izz="2.4796E-05" />
    </inertial>
    <visual>
      <origin
        xyz="0 0 0"
        rpy="0 0 0" />
      <geometry>
        <mesh
          filename="/Users/lr-2002/project/instantcreation/IC_arm_control/ic_arm/meshes/link6.STL" />
      </geometry>
      <material
        name="">
        <color
          rgba="0.69804 0.69804 0.69804 1" />
      </material>
    </visual>
    <collision>
      <origin
        xyz="0 0 0"
        rpy="0 0 0" />
      <geometry>
        <mesh
          filename="/Users/lr-2002/project/instantcreation/IC_arm_control/ic_arm/meshes/link6.STL" />
      </geometry>
    </collision>
  </link>
  <joint
    name="m5-l6"
    type="continuous">
    <origin
      xyz="0.1118 0.063039 0"
      rpy="1.5708 -0.7854 0" />
    <parent
      link="motor5" />
    <child
      link="link6" />
    <axis
      xyz="0 0 1" />
  </joint>
</robot>
