<?xml version="1.0" encoding="utf-8"?>
<!-- This URDF was automatically created by SolidWorks to URDF Exporter! Originally created by Stephen Brawner (brawner@gmail.com) 
		 Commit Version: 1.6.0-4-g7f85cfe  Build Version: 1.6.7995.38578
		 For more information, please see http://wiki.ros.org/sw_urdf_exporter -->
<robot
	name="robot">
	<link
		name="base_link">
		<inertial>
			<origin
				xyz="0.048985 0.048594 0.055075"
				rpy="0 0 0" />
			<mass
				value="1.0009" />
			<inertia
				ixx="0.0024508"
				ixy="-0.00069044"
				ixz="-7.0953E-05"
				iyy="0.0024996"
				iyz="-7.2847E-05"
				izz="0.0041188" />
		</inertial>
		<visual>
			<origin
				xyz="0 0 0"
				rpy="0 0 0" />
			<geometry>
				<mesh
					filename="/Users/lr-2002/project/instantcreation/IC_arm_control/robot/meshes/base_link.STL" />
			</geometry>
			<material
				name="">
				<color
					rgba="1 1 1 1" />
			</material>
		</visual>
		<collision>
			<origin
				xyz="0 0 0"
				rpy="0 0 0" />
			<geometry>
				<mesh
					filename="/Users/lr-2002/project/instantcreation/IC_arm_control/robot/meshes/base_link.STL" />
			</geometry>
		</collision>
	</link>
	<link
		name="joint1_link">
		<inertial>
			<origin
				xyz="-0.1018 -8.6117E-05 0.068088"
				rpy="0 0 0" />
			<mass
				value="0.26909" />
			<inertia
				ixx="0.00057791"
				ixy="-1.1895E-07"
				ixz="0.00013558"
				iyy="0.00076167"
				iyz="3.7617E-08"
				izz="0.00046295" />
		</inertial>
		<visual>
			<origin
				xyz="0 0 0"
				rpy="0 0 0" />
			<geometry>
				<mesh
					filename="/Users/lr-2002/project/instantcreation/IC_arm_control/robot/meshes/joint1_link.STL" />
			</geometry>
			<material
				name="">
				<color
					rgba="0.69804 0.69804 0.69804 1" />
			</material>
		</visual>
		<collision>
			<origin
				xyz="0 0 0"
				rpy="0 0 0" />
			<geometry>
				<mesh
					filename="/Users/lr-2002/project/instantcreation/IC_arm_control/robot/meshes/joint1_link.STL" />
			</geometry>
		</collision>
	</link>
	<joint
		name="joint1"
		type="revolute">
		<origin
			xyz="0.14284 0.14284 0.0323"
			rpy="0 0 3.1416" />
		<parent
			link="base_link" />
		<child
			link="joint1_link" />
		<axis
			xyz="0 0 -1" />
		<limit
			lower="-3.14"
			upper="3.14"
			effort="100"
			velocity="100" />
	</joint>
	<link
		name="joint2_link">
		<inertial>
			<origin
				xyz="-0.0011074 -0.037784 0.033993"
				rpy="0 0 0" />
			<mass
				value="0.12502" />
			<inertia
				ixx="0.00011269"
				ixy="-1.1025E-06"
				ixz="-5.2045E-09"
				iyy="7.5107E-05"
				iyz="-1.7756E-07"
				izz="0.00014835" />
		</inertial>
		<visual>
			<origin
				xyz="0 0 0"
				rpy="0 0 0" />
			<geometry>
				<mesh
					filename="/Users/lr-2002/project/instantcreation/IC_arm_control/robot/meshes/joint2_link.STL" />
			</geometry>
			<material
				name="">
				<color
					rgba="0.69804 0.69804 0.69804 1" />
			</material>
		</visual>
		<collision>
			<origin
				xyz="0 0 0"
				rpy="0 0 0" />
			<geometry>
				<mesh
					filename="/Users/lr-2002/project/instantcreation/IC_arm_control/robot/meshes/joint2_link.STL" />
			</geometry>
		</collision>
	</link>
	<joint
		name="joint2"
		type="revolute">
		<origin
			xyz="-0.2025 -0.00014966 0.13238"
			rpy="0 -1.5708 3.1416" />
		<parent
			link="joint1_link" />
		<child
			link="joint2_link" />
		<axis
			xyz="0 0 -1" />
		<limit
			lower="-3.14"
			upper="3.14"
			effort="100"
			velocity="100" />
	</joint>
	<link
		name="joint3_link">
		<inertial>
			<origin
				xyz="0.017582 0.0033522 0.11575"
				rpy="0 0 0" />
			<mass
				value="0.4683" />
			<inertia
				ixx="0.0014252"
				ixy="-2.04E-05"
				ixz="-2.6747E-05"
				iyy="0.0014163"
				iyz="-6.2138E-06"
				izz="0.00034162" />
		</inertial>
		<visual>
			<origin
				xyz="0 0 0"
				rpy="0 0 0" />
			<geometry>
				<mesh
					filename="/Users/lr-2002/project/instantcreation/IC_arm_control/robot/meshes/joint3_link.STL" />
			</geometry>
			<material
				name="">
				<color
					rgba="0.69804 0.69804 0.69804 1" />
			</material>
		</visual>
		<collision>
			<origin
				xyz="0 0 0"
				rpy="0 0 0" />
			<geometry>
				<mesh
					filename="/Users/lr-2002/project/instantcreation/IC_arm_control/robot/meshes/joint3_link.STL" />
			</geometry>
		</collision>
	</link>
	<joint
		name="joint3"
		type="revolute">
		<origin
			xyz="-0.0023436 -0.079966 0.03425"
			rpy="1.6001 -1.5708 0" />
		<parent
			link="joint2_link" />
		<child
			link="joint3_link" />
		<axis
			xyz="0 0 1" />
		<limit
			lower="-3.14"
			upper="3.14"
			effort="100"
			velocity="100" />
	</joint>
	<link
		name="joint4_link">
		<inertial>
			<origin
				xyz="0.020006 -0.031386 -0.0095063"
				rpy="0 0 0" />
			<mass
				value="0.31246" />
			<inertia
				ixx="0.00059768"
				ixy="9.222E-05"
				ixz="-0.00019694"
				iyy="0.0008237"
				iyz="8.0958E-05"
				izz="0.00070818" />
		</inertial>
		<visual>
			<origin
				xyz="0 0 0"
				rpy="0 0 0" />
			<geometry>
				<mesh
					filename="/Users/lr-2002/project/instantcreation/IC_arm_control/robot/meshes/joint4_link.STL" />
			</geometry>
			<material
				name="">
				<color
					rgba="0.69804 0.69804 0.69804 1" />
			</material>
		</visual>
		<collision>
			<origin
				xyz="0 0 0"
				rpy="0 0 0" />
			<geometry>
				<mesh
					filename="/Users/lr-2002/project/instantcreation/IC_arm_control/robot/meshes/joint4_link.STL" />
			</geometry>
		</collision>
	</link>
	<joint
		name="joint4"
		type="revolute">
		<origin
			xyz="0.0297 0 0.2883"
			rpy="-1.5708 0.029299 -1.5708" />
		<parent
			link="joint3_link" />
		<child
			link="joint4_link" />
		<axis
			xyz="0 0 -1" />
		<limit
			lower="-3.14"
			upper="3.14"
			effort="100"
			velocity="100" />
	</joint>
	<link
		name="joint5_link">
		<inertial>
			<origin
				xyz="0.0010802 0.0014003 -0.05791"
				rpy="0 0 0" />
			<mass
				value="0.18765" />
			<inertia
				ixx="0.00021071"
				ixy="1.1509E-06"
				ixz="-6.7694E-06"
				iyy="0.00020882"
				iyz="7.5439E-06"
				izz="7.3356E-05" />
		</inertial>
		<visual>
			<origin
				xyz="0 0 0"
				rpy="0 0 0" />
			<geometry>
				<mesh
					filename="/Users/lr-2002/project/instantcreation/IC_arm_control/robot/meshes/joint5_link.STL" />
			</geometry>
			<material
				name="">
				<color
					rgba="0.75294 0.75294 0.75294 1" />
			</material>
		</visual>
		<collision>
			<origin
				xyz="0 0 0"
				rpy="0 0 0" />
			<geometry>
				<mesh
					filename="/Users/lr-2002/project/instantcreation/IC_arm_control/robot/meshes/joint5_link.STL" />
			</geometry>
		</collision>
	</link>
	<joint
		name="joint5"
		type="revolute">
		<origin
			xyz="0.088527 -0.051566 0.0617"
			rpy="-1.5482 1.5708 -0.0066939" />
		<parent
			link="joint4_link" />
		<child
			link="joint5_link" />
		<axis
			xyz="0 0 -1" />
		<limit
			lower="-3.14"
			upper="3.14"
			effort="100"
			velocity="100" />
	</joint>
</robot>