<?xml version="1.0" encoding="utf-8"?>
<!-- This URDF was automatically created by SolidWorks to URDF Exporter! Originally created by Stephen Brawner (brawner@gmail.com) 
		 Commit Version: 1.6.0-4-g7f85cfe  Build Version: 1.6.7995.38578
		 For more information, please see http://wiki.ros.org/sw_urdf_exporter -->
<robot
	name="ic1.1.2">
	<!-- BASE ROOT MARKER - Small sphere at base_link origin -->
	<link
		name="base_root_marker">
		<inertial>
			<origin
				xyz="0 0 0"
				rpy="0 0 0" />
			<mass
				value="0.001" />
			<inertia
				ixx="0.000001"
				ixy="0"
				ixz="0"
				iyy="0.000001"
				iyz="0"
				izz="0.000001" />
		</inertial>
		<visual>
			<origin
				xyz="0 0 0"
				rpy="0 0 0" />
			<geometry>
				<sphere radius="0.01" />
			</geometry>
			<material
				name="base_marker_red">
				<color
					rgba="1 0 0 1" />
			</material>
		</visual>
		<collision>
			<origin
				xyz="0 0 0"
				rpy="0 0 0" />
			<geometry>
				<sphere radius="0.01" />
			</geometry>
		</collision>
	</link>

	<!-- Fixed joint to attach marker to base_link -->
	<joint
		name="base_to_marker"
		type="fixed">
		<origin
			xyz="0.47073 0.121 -0.2423"
			rpy="1.57 0 0" />
		<parent
			link="base_root_marker" />
		<child
			link="base_link" />
	</joint>
	<link
		name="base_link">
		<inertial>
			<origin
				xyz="-0.339730098086636 -0.0242287564737764 0.242384128687473"
				rpy="0 0 0" />
			<mass
				value="0.29683973124325" />
			<inertia
				ixx="0.000561968778308919"
				ixy="-0.000557569677341994"
				ixz="-2.6654113978676E-05"
				iyy="0.000942752081522117"
				iyz="-2.1587357005544E-05"
				izz="0.00137504087476319" />
		</inertial>
		<visual>
			<origin
				xyz="0 0 0"
				rpy="0 0 0" />
			<geometry>
				<mesh
					filename="/Users/lr-2002/project/instantcreation/IC_arm_control/ic_arm_urdf/meshes/base_link.STL" />
			</geometry>
			<material
				name="">
				<color
					rgba="1 1 1 1" />
			</material>
		</visual>
		<collision>
			<origin
				xyz="0 0 0"
				rpy="0 0 0" />
			<geometry>
				<mesh
					filename="/Users/lr-2002/project/instantcreation/IC_arm_control/ic_arm_urdf/meshes/base_link.STL" />
			</geometry>
		</collision>
	</link>



	<link
		name="l1">
		<inertial>
			<origin
				xyz="0.127828537833142 -0.00226606089266443 3.21305194839194E-06"
				rpy="0 0 0" />
			<mass
				value="0.478980584273002" />
			<inertia
				ixx="0.000663204848292966"
				ixy="0.00036239570148629"
				ixz="4.29394463686086E-07"
				iyy="0.00114032689080108"
				iyz="3.43883487499989E-07"
				izz="0.00144664886438339" />
		</inertial>
		<visual>
			<origin
				xyz="0 0 0"
				rpy="0 0 0" />
			<geometry>
				<mesh
					filename="/Users/lr-2002/project/instantcreation/IC_arm_control/ic_arm_urdf/meshes/l1.STL" />
			</geometry>
			<material
				name="">
				<color
					rgba="1 1 1 1" />
			</material>
		</visual>
		<collision>
			<origin
				xyz="0 0 0"
				rpy="0 0 0" />
			<geometry>
				<mesh
					filename="/Users/lr-2002/project/instantcreation/IC_arm_control/ic_arm_urdf/meshes/l1.STL" />
			</geometry>
		</collision>
	</link>
	<joint
		name="j1"
		type="continuous">
		<origin
			xyz="-0.29856 0.0020693 0.21104"
			rpy="1.5708 0. 1.4647" />
		<parent
			link="base_link" />
		<child
			link="l1" />
		<axis
			xyz="0 1 0" />
	</joint>
	<link
		name="l2">
		<inertial>
			<origin
				xyz="0.156036085442414 0.0268481985348551 -2.56023143476725E-05"
				rpy="0 0 0" />
			<mass
				value="0.510675561993692" />
			<inertia
				ixx="0.000382861468585297"
				ixy="-2.19262819333773E-07"
				ixz="4.81933954692093E-07"
				iyy="0.00193928520028623"
				iyz="-9.68044541288472E-09"
				izz="0.00187455937482899" />
		</inertial>
		<visual>
			<origin
				xyz="0 0 0"
				rpy="0 0 0" />
			<geometry>
				<mesh
					filename="/Users/lr-2002/project/instantcreation/IC_arm_control/ic_arm_urdf/meshes/l2.STL" />
			</geometry>
			<material
				name="">
				<color
					rgba="1 1 1 1" />
			</material>
		</visual>
		<collision>
			<origin
				xyz="0 0 0"
				rpy="0 0 0" />
			<geometry>
				<mesh
					filename="/Users/lr-2002/project/instantcreation/IC_arm_control/ic_arm_urdf/meshes/l2.STL" />
			</geometry>
		</collision>
	</link>
	<joint
		name="j2"
		type="continuous">
		<origin
			xyz="0.176971378800704 -0.0552999999999993 0"
			rpy="0 1.57 -1.57079632679489" />
		<parent
			link="l1" />
		<child
			link="l2" />
		<axis
			xyz="0 1 0" />
	</joint>
	<link
		name="l3">
		<inertial>
			<origin
				xyz="-0.109943403200528 0.00208057979858922 -1.08037533150251E-06"
				rpy="0 0 0" />
			<mass
				value="0.301661437311036" />
			<inertia
				ixx="0.000143491154639993"
				ixy="-2.5129579364346E-07"
				ixz="-4.05027387114055E-08"
				iyy="0.000242262360164897"
				iyz="1.62108577569322E-08"
				izz="0.000177268625082043" />
		</inertial>
		<visual>
			<origin
				xyz="0 0 0"
				rpy="0 0 0" />
			<geometry>
				<mesh
					filename="/Users/lr-2002/project/instantcreation/IC_arm_control/ic_arm_urdf/meshes/l3.STL" />
			</geometry>
			<material
				name="">
				<color
					rgba="1 1 1 1" />
			</material>
		</visual>
		<collision>
			<origin
				xyz="0 0 0"
				rpy="0 0 0" />
			<geometry>
				<mesh
					filename="/Users/lr-2002/project/instantcreation/IC_arm_control/ic_arm_urdf/meshes/l3.STL" />
			</geometry>
		</collision>
	</link>
	<joint
		name="j3"
		type="continuous">
		<origin
			xyz="0.239291817338248 0.0267286211992953 0"
			rpy="-0 0 3.14" />
		<parent
			link="l2" />
		<child
			link="l3" />
		<axis
			xyz="-1 0 0" />
	</joint>
	<link
		name="l4">
		<inertial>
			<origin
				xyz="-0.0719024636211236 0.0371837584221808 0.0369977170552586"
				rpy="0 0 0" />
			<mass
				value="0.356837818566484" />
			<inertia
				ixx="0.00074455347502792"
				ixy="0.000152142345766084"
				ixz="0.000123700221056116"
				iyy="0.000827958622307639"
				iyz="-0.000209810266491571"
				izz="0.000818475725962542" />
		</inertial>
		<visual>
			<origin
				xyz="0 0 0"
				rpy="0 0 0" />
			<geometry>
				<mesh
					filename="/Users/lr-2002/project/instantcreation/IC_arm_control/ic_arm_urdf/meshes/l4.STL" />
			</geometry>
			<material
				name="">
				<color
					rgba="1 1 1 1" />
			</material>
		</visual>
		<collision>
			<origin
				xyz="0 0 0"
				rpy="0 0 0" />
			<geometry>
				<mesh
					filename="/Users/lr-2002/project/instantcreation/IC_arm_control/ic_arm_urdf/meshes/l4.STL" />
			</geometry>
		</collision>
	</link>
	<joint
		name="j4"
		type="revolute">
		<origin
			xyz="-0.129008182661752 0 0"
			rpy="0 0.087 0" />
		<parent
			link="l3" />
		<child
			link="l4" />
		<axis
			xyz="0 -1 0" />
		<limit
			lower="-1.6248"
			upper="1.5168"
			effort="0"
			velocity="0" />
	</joint>
	<link
		name="l5">
		<inertial>
			<origin
				xyz="0.00405933432369598 -0.00269717440222905 -0.108374524552232"
				rpy="0 0 0" />
			<mass
				value="0.111763033612063" />
			<inertia
				ixx="0.000270532442358034"
				ixy="-1.97454104589701E-06"
				ixz="1.12789222485375E-05"
				iyy="0.000273026809704054"
				iyz="1.17931137142189E-05"
				izz="3.99937954343094E-05" />
		</inertial>
		<visual>
			<origin
				xyz="0 0 0"
				rpy="0 0 0" />
			<geometry>
				<mesh
					filename="/Users/lr-2002/project/instantcreation/IC_arm_control/ic_arm_urdf/meshes/l5.STL" />
			</geometry>
			<material
				name="">
				<color
					rgba="1 1 1 1" />
			</material>
		</visual>
		<collision>
			<origin
				xyz="0 0 0"
				rpy="0 0 0" />
			<geometry>
				<mesh
					filename="/Users/lr-2002/project/instantcreation/IC_arm_control/ic_arm_urdf/meshes/l5.STL" />
			</geometry>
		</collision>
	</link>
	<joint
		name="j5"
		type="continuous">
		<origin
			xyz="-0.0758328769955004 0.0713000000000006 0.0700000000000002"
			rpy="-1.57079632679489 1.22460020901222 -1.57079632679489" />
		<parent
			link="l4" />
		<child
			link="l5" />
		<axis
			xyz="0 0 -1" />
	</joint>
</robot>
